Workbook

Sheet Inicio
B2: 📊 MODELO DE SEGUIMIENTO · PLANEACIÓN ESTRATÉGICA 2026–2030
B3: Arquitectura: 1 hoja por indicador + Tablero Principal consolidado · Horizonte: enero 2026 – diciembre 2030
B5: 🗂️ ESTRUCTURA DEL ARCHIVO
B6: ● | C6: Inicio | D6: Esta hoja: portada e instrucciones.
B7: ● | C7: Parámetros | D7: Catálogo de responsables por indicador (editable) y referencias mensuales IPC/IBR.
B8: ● | C8: Tablero Principal | D8: Vista consolidada de los 25 indicadores. Recoge todos los meses y muestra metas + % cumplimiento por cada año.
B9: ● | C9: IND-01 ... IND-25 | D9: Una hoja por indicador con su captura mensual y cálculo específico.
B11: 🚀 FLUJO DE TRABAJO MENSUAL
B12: 1. Asigne responsables en la hoja Parámetros (catálogo editable).
B13: 2. Para cada indicador, abra su hoja (IND-XX) y registre las variables del mes en las celdas azules.
B14: 3. El resultado mensual, % de cumplimiento, semáforo y avance acumulado se calculan automáticamente.
B15: 4. El Tablero Principal consolida los 25 indicadores en una sola vista ejecutiva.
B16: 5. Las metas anuales son editables en cada hoja. Las marcadas como 'Por definir' deben completarse.
B17: 6. Los responsables se asignan en Parámetros y se propagan a todo el modelo.
B19: 🚦 SEMÁFORO DE CUMPLIMIENTO
B20: ● | C20: 🟢 En meta (Cumple) | D20: ≥ 95%
B21: ● | C21: 🟡 Atención (En riesgo) | D21: 80% – 94,9%
B22: ● | C22: 🔴 Crítico — revisar | D22: < 80%
B23: ● | C23: ⚪ Pendiente | D23: Sin dato / sin meta
B25: 📋 ÍNDICE DE INDICADORES
B26: Código | C26: Perspectiva | D26: Objetivo Específico | E26: Indicador | F26: Frecuencia
B27: IND-01 | C27: 💰 Financiera | D27: Aumento de ingresos | E27: Crecimiento de cartera en líneas de mayor rendimiento | F27: Mensual
B28: IND-02 | C28: 💰 Financiera | D28: Aumento de ingresos | E28: Crecimiento de ingresos operativos | F28: Mensual
B29: IND-03 | C29: 💰 Financiera | D29: Aumento de ingresos | E29: Crecimiento de ingresos por comisiones | F29: Mensual
B30: IND-04 | C30: 💰 Financiera | D30: Aumento de ingresos | E30: Rentabilidad Fondo de Liquidez | F30: Mensual
B31: IND-05 | C31: 💰 Financiera | D31: Reducción de mora | E31: Índice de mora | F31: Mensual
B32: IND-06 | C32: 💰 Financiera | D32: Reducción de mora | E32: Tasa de recuperación | F32: Mensual
B33: IND-07 | C33: 💰 Financiera | D33: Reducción de mora | E33: Tasa de normalización de cartera | F33: Mensual
B34: IND-08 | C34: 💰 Financiera | D34: Crecimiento y remuneración de depósitos | E34: Tasa de crecimiento de ahorros | F34: Mensual
B35: IND-09 | C35: 💰 Financiera | D35: Crecimiento y remuneración de depósitos | E35: Rentabilidad real de los depósitos | F35: Mensual
B36: IND-10 | C36: 💰 Financiera | D36: Rentabilidad y fortalecimiento patrimonial | E36: Suficiencia del Margen | F36: Mensual
B37: IND-11 | C37: 💰 Financiera | D37: Rentabilidad y fortalecimiento patrimonial | E37: Cumplimiento de pago de aportes sociales | F37: Mensual
... B51: IND-25 | C51: 🎓 Aprendizaje | D51: Formación y desarrollo del personal | E51: Clima organizacional y compromiso del personal | F51: Anual

Sheet Tablero Principal
B2: 📊 TABLERO PRINCIPAL DE INDICADORES · PLANEACIÓN ESTRATÉGICA 2026–2030
B3: Vista consolidada · Todos los indicadores · Todos los meses (Ene-2026 → Dic-2030) · Metas y % cumplimiento por año
B5: FICHA DEL INDICADOR | J5: 🎯 METAS ANUALES | O5: SÁBANA MENSUAL · 2026 | AA5: SÁBANA MENSUAL · 2027 | AM5: SÁBANA MENSUAL · 2028 | AY5: SÁBANA MENSUAL · 2029 | BK5: SÁBANA MENSUAL · 2030 | BW5: ✅ % CUMPLIMIENTO ANUAL | CB5: ESTADO
B6: Objetivo Específico | C6: Indicador | D6: Fórmula | E6: Descripción | F6: Unidad | G6: Tendencia | H6: Frecuencia | I6: Responsable | J6: 2026 | K6: 2027 | L6: 2028 | M6: 2029 | N6: 2030 | O6: Ene | P6: Feb | Q6: Mar | R6: Abr | S6: May | T6: Jun | U6: Jul | V6: Ago | W6: Sep | X6: Oct | Y6: Nov | Z6: Dic | AA6: Ene | AB6: Feb | AC6: Mar | AD6: Abr | AE6: May | AF6: Jun | AG6: Jul | AH6: Ago | AI6: Sep | AJ6: Oct | AK6: Nov | AL6: Dic | AM6: Ene | AN6: Feb | AO6: Mar | AP6: Abr | AQ6: May | AR6: Jun | AS6: Jul | AT6: Ago | AU6: Sep | AV6: Oct | AW6: Nov | AX6: Dic | AY6: Ene | AZ6: Feb | BA6: Mar | BB6: Abr | BC6: May | BD6: Jun | BE6: Jul | BF6: Ago | BG6: Sep | BH6: Oct | BI6: Nov | BJ6: Dic | BK6: Ene | BL6: Feb | BM6: Mar | BN6: Abr | BO6: May | BP6: Jun | BQ6: Jul | BR6: Ago | BS6: Sep | BT6: Oct | BU6: Nov | BV6: Dic | BW6: 2026 | BX6: 2027 | BY6: 2028 | BZ6: 2029 | CA6: 2030 | CB6: Semáforo
B7: 💰 PERSPECTIVA FINANCIERA
B8: Aumento de ingresos | C8: Crecimiento de cartera en líneas de mayor rendimiento | D8: Saldo de cartera de líneas de mayor rendimiento ÷ Saldo total de cartera | E8: Mide la participación de las líneas de crédito con mayor tasa efectiva y contribución al margen financiero. Por el momento, Rotativo y Tarjeta de Crédito. | F8: % | G8: Crecer | H8: Mensual | I8: =VLOOKUP("IND-01",Parámetros!$B$6:$F$30,5,FALSE()) -> Gerencia Financiera | J8: ='IND-01'!C14 -> 0.08 | K8: ='IND-01'!C15 -> 0.1 | L8: ='IND-01'!C16 -> 0.12 | M8: ='IND-01'!C17 -> 0.14 | N8: ='IND-01'!C18 -> 0.16 | O8: =IFERROR(IF('IND-01'!G23="","",'IND-01'!G23),"") -> 0.08 | P8: =IFERROR(IF('IND-01'!G24="","",'IND-01'!G24),"") -> 0.08 | Q8: =IFERROR(IF('IND-01'!G25="","",'IND-01'!G25),"") -> 0.08 | R8: =IFERROR(IF('IND-01'!G26="","",'IND-01'!G26),"") -> 0.08 | S8: =IFERROR(IF('IND-01'!G27="","",'IND-01'!G27),"") -> 0.08 | T8: =IFERROR(IF('IND-01'!G28="","",'IND-01'!G28),"") -> 0.08 | U8: =IFERROR(IF('IND-01'!G29="","",'IND-01'!G29),"") -> 0.08 | V8: =IFERROR(IF('IND-01'!G30="","",'IND-01'!G30),"") -> 0.08 | W8: =IFERROR(IF('IND-01'!G31="","",'IND-01'!G31),"") -> 0.08 | X8: =IFERROR(IF('IND-01'!G32="","",'IND-01'!G32),"") -> 0.08 | Y8: =IFERROR(IF('IND-01'!G33="","",'IND-01'!G33),"") -> 0.08 | Z8: =IFERROR(IF('IND-01'!G34="","",'IND-01'!G34),"") -> 0.08 | AA8: =IFERROR(IF('IND-01'!G35="","",'IND-01'!G35),"") -> 0.09 | AB8: =IFERROR(IF('IND-01'!G36="","",'IND-01'!G36),"") -> 0.091 | AC8: =IFERROR(IF('IND-01'!G37="","",'IND-01'!G37),"") -> 0.092 | AD8: =IFERROR(IF('IND-01'!G38="","",'IND-01'!G38),"") -> 0.093 | AE8: =IFERROR(IF('IND-01'!G39="","",'IND-01'!G39),"") -> 0.094 | AF8: =IFERROR(IF('IND-01'!G40="","",'IND-01'!G40),"") -> 0.095 | AG8: =IFERROR(IF('IND-01'!G41="","",'IND-01'!G41),"") | AH8: =IFERROR(IF('IND-01'!G42="","",'IND-01'!G42),"") | AI8: =IFERROR(IF('IND-01'!G43="","",'IND-01'!G43),"") | AJ8: =IFERROR(IF('IND-01'!G44="","",'IND-01'!G44),"") | AK8: =IFERROR(IF('IND-01'!G45="","",'IND-01'!G45),"") | AL8: =IFERROR(IF('IND-01'!G46="","",'IND-01'!G46),"") | AM8: =IFERROR(IF('IND-01'!G47="","",'IND-01'!G47),"") | AN8: =IFERROR(IF('IND-01'!G48="","",'IND-01'!G48),"") | AO8: =IFERROR(IF('IND-01'!G49="","",'IND-01'!G49),"") | AP8: =IFERROR(IF('IND-01'!G50="","",'IND-01'!G50),"") | AQ8: =IFERROR(IF('IND-01'!G51="","",'IND-01'!G51),"") | AR8: =IFERROR(IF('IND-01'!G52="","",'IND-01'!G52),"") | AS8: =IFERROR(IF('IND-01'!G53="","",'IND-01'!G53),"") | AT8: =IFERROR(IF('IND-01'!G54="","",'IND-01'!G54),"") | AU8: =IFERROR(IF('IND-01'!G55="","",'IND-01'!G55),"") | AV8: =IFERROR(IF('IND-01'!G56="","",'IND-01'!G56),"") | AW8: =IFERROR(IF('IND-01'!G57="","",'IND-01'!G57),"") | AX8: =IFERROR(IF('IND-01'!G58="","",'IND-01'!G58),"") | AY8: =IFERROR(IF('IND-01'!G59="","",'IND-01'!G59),"") | AZ8: =IFERROR(IF('IND-01'!G60="","",'IND-01'!G60),"") | BA8: =IFERROR(IF('IND-01'!G61="","",'IND-01'!G61),"") | BB8: =IFERROR(IF('IND-01'!G62="","",'IND-01'!G62),"") | BC8: =IFERROR(IF('IND-01'!G63="","",'IND-01'!G63),"") | BD8: =IFERROR(IF('IND-01'!G64="","",'IND-01'!G64),"") | BE8: =IFERROR(IF('IND-01'!G65="","",'IND-01'!G65),"") | BF8: =IFERROR(IF('IND-01'!G66="","",'IND-01'!G66),"") | BG8: =IFERROR(IF('IND-01'!G67="","",'IND-01'!G67),"") | BH8: =IFERROR(IF('IND-01'!G68="","",'IND-01'!G68),"") | BI8: =IFERROR(IF('IND-01'!G69="","",'IND-01'!G69),"") | BJ8: =IFERROR(IF('IND-01'!G70="","",'IND-01'!G70),"") | BK8: =IFERROR(IF('IND-01'!G71="","",'IND-01'!G71),"") | BL8: =IFERROR(IF('IND-01'!G72="","",'IND-01'!G72),"") | BM8: =IFERROR(IF('IND-01'!G73="","",'IND-01'!G73),"") | BN8: =IFERROR(IF('IND-01'!G74="","",'IND-01'!G74),"") | BO8: =IFERROR(IF('IND-01'!G75="","",'IND-01'!G75),"") | BP8: =IFERROR(IF('IND-01'!G76="","",'IND-01'!G76),"") | BQ8: =IFERROR(IF('IND-01'!G77="","",'IND-01'!G77),"") | BR8: =IFERROR(IF('IND-01'!G78="","",'IND-01'!G78),"") | BS8: =IFERROR(IF('IND-01'!G79="","",'IND-01'!G79),"") | BT8: =IFERROR(IF('IND-01'!G80="","",'IND-01'!G80),"") | BU8: =IFERROR(IF('IND-01'!G81="","",'IND-01'!G81),"") | BV8: =IFERROR(IF('IND-01'!G82="","",'IND-01'!G82),"") | BW8: =IFERROR(AVERAGE('IND-01'!I23:I34),"") -> 1 | BX8: =IFERROR(AVERAGE('IND-01'!I35:I46),"") -> 0.925 | BY8: =IFERROR(AVERAGE('IND-01'!I47:I58),"") | BZ8: =IFERROR(AVERAGE('IND-01'!I59:I70),"") | CA8: =IFERROR(AVERAGE('IND-01'!I71:I82),"") | CB8: =IFERROR(IF(LOOKUP(2,1/((BW8:CA8<>"")*(ISNUMBER(BW8:CA8))),BW8:CA8)>=0.95,"🟢 Cumple",IF(LOOKUP(2,1/((BW8:CA8<>"")*(ISNUMBER(BW8:CA8))),BW8:CA8)>=0.8,"🟡 En riesgo","🔴 Crítico")),"⚪ Pendiente") -> 🟡 En riesgo
B9: Aumento de ingresos | C9: Crecimiento de ingresos operativos | D9: (Ingresos de cartera final − Ingresos de cartera inicial) ÷ Ingresos de cartera inicial | E9: Refleja el impacto directo de la colocación sobre los ingresos financieros. | F9: % | G9: Crecer | H9: Mensual | I9: =VLOOKUP("IND-02",Parámetros!$B$6:$F$30,5,FALSE()) -> Gerencia Financiera | J9: ='IND-02'!C14 -> 0.1 | K9: ='IND-02'!C15 -> 0.1 | L9: ='IND-02'!C16 -> 0.1 | M9: ='IND-02'!C17 -> 0.1 | N9: ='IND-02'!C18 -> 0.1 | O9: =IFERROR(IF('IND-02'!F23="","",'IND-02'!F23),"") | P9: =IFERROR(IF('IND-02'!F24="","",'IND-02'!F24),"") -> 0.008 | Q9: =IFERROR(IF('IND-02'!F25="","",'IND-02'!F25),"") -> 0.008 | R9: =IFERROR(IF('IND-02'!F26="","",'IND-02'!F26),"") -> 0.008 | S9: =IFERROR(IF('IND-02'!F27="","",'IND-02'!F27),"") -> 0.008 | T9: =IFERROR(IF('IND-02'!F28="","",'IND-02'!F28),"") -> 0.008 | U9: =IFERROR(IF('IND-02'!F29="","",'IND-02'!F29),"") -> 0.008 | V9: =IFERROR(IF('IND-02'!F30="","",'IND-02'!F30),"") -> 0.008 | W9: =IFERROR(IF('IND-02'!F31="","",'IND-02'!F31),"") -> 0.008 | X9: =IFERROR(IF('IND-02'!F32="","",'IND-02'!F32),"") -> 0.008 | Y9: =IFERROR(IF('IND-02'!F33="","",'IND-02'!F33),"") -> 0.008 | Z9: =IFERROR(IF('IND-02'!F34="","",'IND-02'!F34),"") -> 0.008 | AA9: =IFERROR(IF('IND-02'!F35="","",'IND-02'!F35),"") -> 0.008 | AB9: =IFERROR(IF('IND-02'!F36="","",'IND-02'!F36),"") -> 0.008 | AC9: =IFERROR(IF('IND-02'!F37="","",'IND-02'!F37),"") -> 0.008 | AD9: =IFERROR(IF('IND-02'!F38="","",'IND-02'!F38),"") -> 0.008 | AE9: =IFERROR(IF('IND-02'!F39="","",'IND-02'!F39),"") -> 0.008 | AF9: =IFERROR(IF('IND-02'!F40="","",'IND-02'!F40),"") -> 0.008 | AG9: =IFERROR(IF('IND-02'!F41="","",'IND-02'!F41),"") | AH9: =IFERROR(IF('IND-02'!F42="","",'IND-02'!F42),"") | AI9: =IFERROR(IF('IND-02'!F43="","",'IND-02'!F43),"") | AJ9: =IFERROR(IF('IND-02'!F44="","",'IND-02'!F44),"") | AK9: =IFERROR(IF('IND-02'!F45="","",'IND-02'!F45),"") | AL9: =IFERROR(IF('IND-02'!F46="","",'IND-02'!F46),"") | AM9: =IFERROR(IF('IND-02'!F47="","",'IND-02'!F47),"") | AN9: =IFERROR(IF('IND-02'!F48="","",'IND-02'!F48),"") | AO9: =IFERROR(IF('IND-02'!F49="","",'IND-02'!F49),"") | AP9: =IFERROR(IF('IND-02'!F50="","",'IND-02'!F50),"") | AQ9: =IFERROR(IF('IND-02'!F51="","",'IND-02'!F51),"") | AR9: =IFERROR(IF('IND-02'!F52="","",'IND-02'!F52),"") | AS9: =IFERROR(IF('IND-02'!F53="","",'IND-02'!F53),"") | AT9: =IFERROR(IF('IND-02'!F54="","",'IND-02'!F54),"") | AU9: =IFERROR(IF('IND-02'!F55="","",'IND-02'!F55),"") | AV9: =IFERROR(IF('IND-02'!F56="","",'IND-02'!F56),"") | AW9: =IFERROR(IF('IND-02'!F57="","",'IND-02'!F57),"") | AX9: =IFERROR(IF('IND-02'!F58="","",'IND-02'!F58),"") | AY9: =IFERROR(IF('IND-02'!F59="","",'IND-02'!F59),"") | AZ9: =IFERROR(IF('IND-02'!F60="","",'IND-02'!F60),"") | BA9: =IFERROR(IF('IND-02'!F61="","",'IND-02'!F61),"") | BB9: =IFERROR(IF('IND-02'!F62="","",'IND-02'!F62),"") | BC9: =IFERROR(IF('IND-02'!F63="","",'IND-02'!F63),"") | BD9: =IFERROR(IF('IND-02'!F64="","",'IND-02'!F64),"") | BE9: =IFERROR(IF('IND-02'!F65="","",'IND-02'!F65),"") | BF9: =IFERROR(IF('IND-02'!F66="","",'IND-02'!F66),"") | BG9: =IFERROR(IF('IND-02'!F67="","",'IND-02'!F67),"") | BH9: =IFERROR(IF('IND-02'!F68="","",'IND-02'!F68),"") | BI9: =IFERROR(IF('IND-02'!F69="","",'IND-02'!F69),"") | BJ9: =IFERROR(IF('IND-02'!F70="","",'IND-02'!F70),"") | BK9: =IFERROR(IF('IND-02'!F71="","",'IND-02'!F71),"") | BL9: =IFERROR(IF('IND-02'!F72="","",'IND-02'!F72),"") | BM9: =IFERROR(IF('IND-02'!F73="","",'IND-02'!F73),"") | BN9: =IFERROR(IF('IND-02'!F74="","",'IND-02'!F74),"") | BO9: =IFERROR(IF('IND-02'!F75="","",'IND-02'!F75),"") | BP9: =IFERROR(IF('IND-02'!F76="","",'IND-02'!F76),"") | BQ9: =IFERROR(IF('IND-02'!F77="","",'IND-02'!F77),"") | BR9: =IFERROR(IF('IND-02'!F78="","",'IND-02'!F78),"") | BS9: =IFERROR(IF('IND-02'!F79="","",'IND-02'!F79),"") | BT9: =IFERROR(IF('IND-02'!F80="","",'IND-02'!F80),"") | BU9: =IFERROR(IF('IND-02'!F81="","",'IND-02'!F81),"") | BV9: =IFERROR(IF('IND-02'!F82="","",'IND-02'!F82),"") | BW9: =IFERROR(AVERAGE('IND-02'!H23:H34),"") -> 0.08 | BX9: =IFERROR(AVERAGE('IND-02'!H35:H46),"") -> 0.08 | BY9: =IFERROR(AVERAGE('IND-02'!H47:H58),"") | BZ9: =IFERROR(AVERAGE('IND-02'!H59:H70),"") | CA9: =IFERROR(AVERAGE('IND-02'!H71:H82),"") | CB9: =IFERROR(IF(LOOKUP(2,1/((BW9:CA9<>"")*(ISNUMBER(BW9:CA9))),BW9:CA9)>=0.95,"🟢 Cumple",IF(LOOKUP(2,1/((BW9:CA9<>"")*(ISNUMBER(BW9:CA9))),BW9:CA9)>=0.8,"🟡 En riesgo","🔴 Crítico")),"⚪ Pendiente") -> 🔴 Crítico
B10: Aumento de ingresos | C10: Crecimiento de ingresos por comisiones | D10: (Ingresos por comisiones final − Ingresos por comisiones inicial) ÷ Ingresos por comisiones inicial | E10: Mide el incremento de ingresos derivados del uso de servicios no financieros (convenios). | F10: % | G10: Crecer | H10: Mensual | I10: =VLOOKUP("IND-03",Parámetros!$B$6:$F$30,5,FALSE()) -> Cartera | J10: ='IND-03'!C14 -> 0.035 | K10: ='IND-03'!C15 -> 0.035 | L10: ='IND-03'!C16 -> 0.035 | M10: ='IND-03'!C17 -> 0.035 | N10: ='IND-03'!C18 -> 0.035 | O10: =IFERROR(IF('IND-03'!F23="","",'IND-03'!F23),"") | P10: =IFERROR(IF('IND-03'!F24="","",'IND-03'!F24),"") | Q10: =IFERROR(IF('IND-03'!F25="","",'IND-03'!F25),"") | R10: =IFERROR(IF('IND-03'!F26="","",'IND-03'!F26),"") | S10: =IFERROR(IF('IND-03'!F27="","",'IND-03'!F27),"") | T10: =IFERROR(IF('IND-03'!F28="","",'IND-03'!F28),"") | U10: =IFERROR(IF('IND-03'!F29="","",'IND-03'!F29),"") | V10: =IFERROR(IF('IND-03'!F30="","",'IND-03'!F30),"") | W10: =IFERROR(IF('IND-03'!F31="","",'IND-03'!F31),"") | X10: =IFERROR(IF('IND-03'!F32="","",'IND-03'!F32),"") | Y10: =IFERROR(IF('IND-03'!F33="","",'IND-03'!F33),"") | Z10: =IFERROR(IF('IND-03'!F34="","",'IND-03'!F34),"") | AA10: =IFERROR(IF('IND-03'!F35="","",'IND-03'!F35),"") | AB10: =IFERROR(IF('IND-03'!F36="","",'IND-03'!F36),"") | AC10: =IFERROR(IF('IND-03'!F37="","",'IND-03'!F37),"") | AD10: =IFERROR(IF('IND-03'!F38="","",'IND-03'!F38),"") | AE10: =IFERROR(IF('IND-03'!F39="","",'IND-03'!F39),"") | AF10: =IFERROR(IF('IND-03'!F40="","",'IND-03'!F40),"") | AG10: =IFERROR(IF('IND-03'!F41="","",'IND-03'!F41),"") | AH10: =IFERROR(IF('IND-03'!F42="","",'IND-03'!F42),"") | AI10: =IFERROR(IF('IND-03'!F43="","",'IND-03'!F43),"") | AJ10: =IFERROR(IF('IND-03'!F44="","",'IND-03'!F44),"") | AK10: =IFERROR(IF('IND-03'!F45="","",'IND-03'!F45),"") | AL10: =IFERROR(IF('IND-03'!F46="","",'IND-03'!F46),"") | AM10: =IFERROR(IF('IND-03'!F47="","",'IND-03'!F47),"") | AN10: =IFERROR(IF('IND-03'!F48="","",'IND-03'!F48),"") | AO10: =IFERROR(IF('IND-03'!F49="","",'IND-03'!F49),"") | AP10: =IFERROR(IF('IND-03'!F50="","",'IND-03'!F50),"") | AQ10: =IFERROR(IF('IND-03'!F51="","",'IND-03'!F51),"") | AR10: =IFERROR(IF('IND-03'!F52="","",'IND-03'!F52),"") | AS10: =IFERROR(IF('IND-03'!F53="","",'IND-03'!F53),"") | AT10: =IFERROR(IF('IND-03'!F54="","",'IND-03'!F54),"") | AU10: =IFERROR(IF('IND-03'!F55="","",'IND-03'!F55),"") | AV10: =IFERROR(IF('IND-03'!F56="","",'IND-03'!F56),"") | AW10: =IFERROR(IF('IND-03'!F57="","",'IND-03'!F57),"") | AX10: =IFERROR(IF('IND-03'!F58="","",'IND-03'!F58),"") | AY10: =IFERROR(IF('IND-03'!F59="","",'IND-03'!F59),"") | AZ10: =IFERROR(IF('IND-03'!F60="","",'IND-03'!F60),"") | BA10: =IFERROR(IF('IND-03'!F61="","",'IND-03'!F61),"") | BB10: =IFERROR(IF('IND-03'!F62="","",'IND-03'!F62),"") | BC10: =IFERROR(IF('IND-03'!F63="","",'IND-03'!F63),"") | BD10: =IFERROR(IF('IND-03'!F64="","",'IND-03'!F64),"") | BE10: =IFERROR(IF('IND-03'!F65="","",'IND-03'!F65),"") | BF10: =IFERROR(IF('IND-03'!F66="","",'IND-03'!F66),"") | BG10: =IFERROR(IF('IND-03'!F67="","",'IND-03'!F67),"") | BH10: =IFERROR(IF('IND-03'!F68="","",'IND-03'!F68),"") | BI10: =IFERROR(IF('IND-03'!F69="","",'IND-03'!F69),"") | BJ10: =IFERROR(IF('IND-03'!F70="","",'IND-03'!F70),"") | BK10: =IFERROR(IF('IND-03'!F71="","",'IND-03'!F71),"") | BL10: =IFERROR(IF('IND-03'!F72="","",'IND-03'!F72),"") | BM10: =IFERROR(IF('IND-03'!F73="","",'IND-03'!F73),"") | BN10: =IFERROR(IF('IND-03'!F74="","",'IND-03'!F74),"") | BO10: =IFERROR(IF('IND-03'!F75="","",'IND-03'!F75),"") | BP10: =IFERROR(IF('IND-03'!F76="","",'IND-03'!F76),"") | BQ10: =IFERROR(IF('IND-03'!F77="","",'IND-03'!F77),"") | BR10: =IFERROR(IF('IND-03'!F78="","",'IND-03'!F78),"") | BS10: =IFERROR(IF('IND-03'!F79="","",'IND-03'!F79),"") | BT10: =IFERROR(IF('IND-03'!F80="","",'IND-03'!F80),"") | BU10: =IFERROR(IF('IND-03'!F81="","",'IND-03'!F81),"") | BV10: =IFERROR(IF('IND-03'!F82="","",'IND-03'!F82),"") | BW10: =IFERROR(AVERAGE('IND-03'!H23:H34),"") | BX10: =IFERROR(AVERAGE('IND-03'!H35:H46),"") | BY10: =IFERROR(AVERAGE('IND-03'!H47:H58),"") | BZ10: =IFERROR(AVERAGE('IND-03'!H59:H70),"") | CA10: =IFERROR(AVERAGE('IND-03'!H71:H82),"") | CB10: =IFERROR(IF(LOOKUP(2,1/((BW10:CA10<>"")*(ISNUMBER(BW10:CA10))),BW10:CA10)>=0.95,"🟢 Cumple",IF(LOOKUP(2,1/((BW10:CA10<>"")*(ISNUMBER(BW10:CA10))),BW10:CA10)>=0.8,"🟡 En riesgo","🔴 Crítico")),"⚪ Pendiente") -> ⚪ Pendiente
B11: Aumento de ingresos | C11: Rentabilidad Fondo de Liquidez | D11: Tasa promedio ponderada de rentabilidad del fondo de liquidez − IBR | E11: Mide la capacidad de generar rentabilidad por encima del mercado. | F11: Puntos básicos | G11: Crecer | H11: Mensual | I11: =VLOOKUP("IND-04",Parámetros!$B$6:$F$30,5,FALSE()) -> Tesorería | J11: ='IND-04'!C14 -> -200 | K11: ='IND-04'!C15 -> -200 | L11: ='IND-04'!C16 -> -200 | M11: ='IND-04'!C17 -> -200 | N11: ='IND-04'!C18 -> -200 | O11: =IFERROR(IF('IND-04'!G23="","",'IND-04'!G23),"") | P11: =IFERROR(IF('IND-04'!G24="","",'IND-04'!G24),"") | Q11: =IFERROR(IF('IND-04'!G25="","",'IND-04'!G25),"") | R11: =IFERROR(IF('IND-04'!G26="","",'IND-04'!G26),"") | S11: =IFERROR(IF('IND-04'!G27="","",'IND-04'!G27),"") | T11: =IFERROR(IF('IND-04'!G28="","",'IND-04'!G28),"") | U11: =IFERROR(IF('IND-04'!G29="","",'IND-04'!G29),"") | V11: =IFERROR(IF('IND-04'!G30="","",'IND-04'!G30),"") | W11: =IFERROR(IF('IND-04'!G31="","",'IND-04'!G31),"") | X11: =IFERROR(IF('IND-04'!G32="","",'IND-04'!G32),"") | Y11: =IFERROR(IF('IND-04'!G33="","",'IND-04'!G33),"") | Z11: =IFERROR(IF('IND-04'!G34="","",'IND-04'!G34),"") | AA11: =IFERROR(IF('IND-04'!G35="","",'IND-04'!G35),"") | AB11: =IFERROR(IF('IND-04'!G36="","",'IND-04'!G36),"") | AC11: =IFERROR(IF('IND-04'!G37="","",'IND-04'!G37),"") | AD11: =IFERROR(IF('IND-04'!G38="","",'IND-04'!G38),"") | AE11: =IFERROR(IF('IND-04'!G39="","",'IND-04'!G39),"") | AF11: =IFERROR(IF('IND-04'!G40="","",'IND-04'!G40),"") | AG11: =IFERROR(IF('IND-04'!G41="","",'IND-04'!G41),"") | AH11: =IFERROR(IF('IND-04'!G42="","",'IND-04'!G42),"") | AI11: =IFERROR(IF('IND-04'!G43="","",'IND-04'!G43),"") | AJ11: =IFERROR(IF('IND-04'!G44="","",'IND-04'!G44),"") | AK11: =IFERROR(IF('IND-04'!G45="","",'IND-04'!G45),"") | AL11: =IFERROR(IF('IND-04'!G46="","",'IND-04'!G46),"") | AM11: =IFERROR(IF('IND-04'!G47="","",'IND-04'!G47),"") | AN11: =IFERROR(IF('IND-04'!G48="","",'IND-04'!G48),"") | AO11: =IFERROR(IF('IND-04'!G49="","",'IND-04'!G49),"") | AP11: =IFERROR(IF('IND-04'!G50="","",'IND-04'!G50),"") | AQ11: =IFERROR(IF('IND-04'!G51="","",'IND-04'!G51),"") | AR11: =IFERROR(IF('IND-04'!G52="","",'IND-04'!G52),"") | AS11: =IFERROR(IF('IND-04'!G53="","",'IND-04'!G53),"") | AT11: =IFERROR(IF('IND-04'!G54="","",'IND-04'!G54),"") | AU11: =IFERROR(IF('IND-04'!G55="","",'IND-04'!G55),"") | AV11: =IFERROR(IF('IND-04'!G56="","",'IND-04'!G56),"") | AW11: =IFERROR(IF('IND-04'!G57="","",'IND-04'!G57),"") | AX11: =IFERROR(IF('IND-04'!G58="","",'IND-04'!G58),"") | AY11: =IFERROR(IF('IND-04'!G59="","",'IND-04'!G59),"") | AZ11: =IFERROR(IF('IND-04'!G60="","",'IND-04'!G60),"") | BA11: =IFERROR(IF('IND-04'!G61="","",'IND-04'!G61),"") | BB11: =IFERROR(IF('IND-04'!G62="","",'IND-04'!G62),"") | BC11: =IFERROR(IF('IND-04'!G63="","",'IND-04'!G63),"") | BD11: =IFERROR(IF('IND-04'!G64="","",'IND-04'!G64),"") | BE11: =IFERROR(IF('IND-04'!G65="","",'IND-04'!G65),"") | BF11: =IFERROR(IF('IND-04'!G66="","",'IND-04'!G66),"") | BG11: =IFERROR(IF('IND-04'!G67="","",'IND-04'!G67),"") | BH11: =IFERROR(IF('IND-04'!G68="","",'IND-04'!G68),"") | BI11: =IFERROR(IF('IND-04'!G69="","",'IND-04'!G69),"") | BJ11: =IFERROR(IF('IND-04'!G70="","",'IND-04'!G70),"") | BK11: =IFERROR(IF('IND-04'!G71="","",'IND-04'!G71),"") | BL11: =IFERROR(IF('IND-04'!G72="","",'IND-04'!G72),"") | BM11: =IFERROR(IF('IND-04'!G73="","",'IND-04'!G73),"") | BN11: =IFERROR(IF('IND-04'!G74="","",'IND-04'!G74),"") | BO11: =IFERROR(IF('IND-04'!G75="","",'IND-04'!G75),"") | BP11: =IFERROR(IF('IND-04'!G76="","",'IND-04'!G76),"") | BQ11: =IFERROR(IF('IND-04'!G77="","",'IND-04'!G77),"") | BR11: =IFERROR(IF('IND-04'!G78="","",'IND-04'!G78),"") | BS11: =IFERROR(IF('IND-04'!G79="","",'IND-04'!G79),"") | BT11: =IFERROR(IF('IND-04'!G80="","",'IND-04'!G80),"") | BU11: =IFERROR(IF('IND-04'!G81="","",'IND-04'!G81),"") | BV11: =IFERROR(IF('IND-04'!G82="","",'IND-04'!G82),"") | BW11: =IFERROR(AVERAGE('IND-04'!I23:I34),"") | BX11: =IFERROR(AVERAGE('IND-04'!I35:I46),"") | BY11: =IFERROR(AVERAGE('IND-04'!I47:I58),"") | BZ11: =IFERROR(AVERAGE('IND-04'!I59:I70),"") | CA11: =IFERROR(AVERAGE('IND-04'!I71:I82),"") | CB11: =IFERROR(IF(LOOKUP(2,1/((BW11:CA11<>"")*(ISNUMBER(BW11:CA11))),BW11:CA11)>=0.95,"🟢 Cumple",IF(LOOKUP(2,1/((BW11:CA11<>"")*(ISNUMBER(BW11:CA11))),BW11:CA11)>=0.8,"🟡 En riesgo","🔴 Crítico")),"⚪ Pendiente") -> ⚪ Pendiente
B12: Reducción de mora | C12: Índice de mora | D12: Saldo de cartera ≥ B ÷ Saldo total de cartera | E12: Mide el nivel de morosidad de la cartera por crédito, sin aplicación de arrastres o riesgo. | F12: % | G12: Reducir | H12: Mensual | I12: =VLOOKUP("IND-05",Parámetros!$B$6:$F$30,5,FALSE()) -> Cartera | J12: ='IND-05'!C14 -> 0.05 | K12: ='IND-05'!C15 -> 0.05 | L12: ='IND-05'!C16 -> 0.05 | M12: ='IND-05'!C17 -> 0.05 | N12: ='IND-05'!C18 -> 0.05 | O12: =IFERROR(IF('IND-05'!G23="","",'IND-05'!G23),"") -> 0.045 | P12: =IFERROR(IF('IND-05'!G24="","",'IND-05'!G24),"") -> 0.046 | Q12: =IFERROR(IF('IND-05'!G25="","",'IND-05'!G25),"") -> 0.047 | R12: =IFERROR(IF('IND-05'!G26="","",'IND-05'!G26),"") -> 0.048 | S12: =IFERROR(IF('IND-05'!G27="","",'IND-05'!G27),"") -> 0.049 | T12: =IFERROR(IF('IND-05'!G28="","",'IND-05'!G28),"") -> 0.05 | U12: =IFERROR(IF('IND-05'!G29="","",'IND-05'!G29),"") -> 0.051 | V12: =IFERROR(IF('IND-05'!G30="","",'IND-05'!G30),"") -> 0.052 | W12: =IFERROR(IF('IND-05'!G31="","",'IND-05'!G31),"") -> 0.053 | X12: =IFERROR(IF('IND-05'!G32="","",'IND-05'!G32),"") -> 0.054 | Y12: =IFERROR(IF('IND-05'!G33="","",'IND-05'!G33),"") -> 0.055 | Z12: =IFERROR(IF('IND-05'!G34="","",'IND-05'!G34),"") -> 0.056 | AA12: =IFERROR(IF('IND-05'!G35="","",'IND-05'!G35),"") -> 0.1 | AB12: =IFERROR(IF('IND-05'!G36="","",'IND-05'!G36),"") -> 0.1 | AC12: =IFERROR(IF('IND-05'!G37="","",'IND-05'!G37),"") -> 0.1 | AD12: =IFERROR(IF('IND-05'!G38="","",'IND-05'!G38),"") | AE12: =IFERROR(IF('IND-05'!G39="","",'IND-05'!G39),"") | AF12: =IFERROR(IF('IND-05'!G40="","",'IND-05'!G40),"") | AG12: =IFERROR(IF('IND-05'!G41="","",'IND-05'!G41),"") | AH12: =IFERROR(IF('IND-05'!G42="","",'IND-05'!G42),"") | AI12: =IFERROR(IF('IND-05'!G43="","",'IND-05'!G43),"") | AJ12: =IFERROR(IF('IND-05'!G44="","",'IND-05'!G44),"") | AK12: =IFERROR(IF('IND-05'!G45="","",'IND-05'!G45),"") | AL12: =IFERROR(IF('IND-05'!G46="","",'IND-05'!G46),"") | AM12: =IFERROR(IF('IND-05'!G47="","",'IND-05'!G47),"") | AN12: =IFERROR(IF('IND-05'!G48="","",'IND-05'!G48),"") | AO12: =IFERROR(IF('IND-05'!G49="","",'IND-05'!G49),"") | AP12: =IFERROR(IF('IND-05'!G50="","",'IND-05'!G50),"") | AQ12: =IFERROR(IF('IND-05'!G51="","",'IND-05'!G51),"") | AR12: =IFERROR(IF('IND-05'!G52="","",'IND-05'!G52),"") | AS12: =IFERROR(IF('IND-05'!G53="","",'IND-05'!G53),"") | AT12: =IFERROR(IF('IND-05'!G54="","",'IND-05'!G54),"") | AU12: =IFERROR(IF('IND-05'!G55="","",'IND-05'!G55),"") | AV12: =IFERROR(IF('IND-05'!G56="","",'IND-05'!G56),"") | AW12: =IFERROR(IF('IND-05'!G57="","",'IND-05'!G57),"") | AX12: =IFERROR(IF('IND-05'!G58="","",'IND-05'!G58),"") | AY12: =IFERROR(IF('IND-05'!G59="","",'IND-05'!G59),"") | AZ12: =IFERROR(IF('IND-05'!G60="","",'IND-05'!G60),"") | BA12: =IFERROR(IF('IND-05'!G61="","",'IND-05'!G61),"") | BB12: =IFERROR(IF('IND-05'!G62="","",'IND-05'!G62),"") | BC12: =IFERROR(IF('IND-05'!G63="","",'IND-05'!G63),"") | BD12: =IFERROR(IF('IND-05'!G64="","",'IND-05'!G64),"") | BE12: =IFERROR(IF('IND-05'!G65="","",'IND-05'!G65),"") | BF12: =IFERROR(IF('IND-05'!G66="","",'IND-05'!G66),"") | BG12: =IFERROR(IF('IND-05'!G67="","",'IND-05'!G67),"") | BH12: =IFERROR(IF('IND-05'!G68="","",'IND-05'!G68),"") | BI12: =IFERROR(IF('IND-05'!G69="","",'IND-05'!G69),"") | BJ12: =IFERROR(IF('IND-05'!G70="","",'IND-05'!G70),"") | BK12: =IFERROR(IF('IND-05'!G71="","",'IND-05'!G71),"") | BL12: =IFERROR(IF('IND-05'!G72="","",'IND-05'!G72),"") | BM12: =IFERROR(IF('IND-05'!G73="","",'IND-05'!G73),"") | BN12: =IFERROR(IF('IND-05'!G74="","",'IND-05'!G74),"") | BO12: =IFERROR(IF('IND-05'!G75="","",'IND-05'!G75),"") | BP12: =IFERROR(IF('IND-05'!G76="","",'IND-05'!G76),"") | BQ12: =IFERROR(IF('IND-05'!G77="","",'IND-05'!G77),"") | BR12: =IFERROR(IF('IND-05'!G78="","",'IND-05'!G78),"") | BS12: =IFERROR(IF('IND-05'!G79="","",'IND-05'!G79),"") | BT12: =IFERROR(IF('IND-05'!G80="","",'IND-05'!G80),"") | BU12: =IFERROR(IF('IND-05'!G81="","",'IND-05'!G81),"") | BV12: =IFERROR(IF('IND-05'!G82="","",'IND-05'!G82),"") | BW12: =IFERROR(AVERAGE('IND-05'!I23:I34),"") -> 0.99476442 | BX12: =IFERROR(AVERAGE('IND-05'!I35:I46),"") -> 0.5 | BY12: =IFERROR(AVERAGE('IND-05'!I47:I58),"") | BZ12: =IFERROR(AVERAGE('IND-05'!I59:I70),"") | CA12: =IFERROR(AVERAGE('IND-05'!I71:I82),"") | CB12: =IFERROR(IF(LOOKUP(2,1/((BW12:CA12<>"")*(ISNUMBER(BW12:CA12))),BW12:CA12)>=0.95,"🟢 Cumple",IF(LOOKUP(2,1/((BW12:CA12<>"")*(ISNUMBER(BW12:CA12))),BW12:CA12)>=0.8,"🟡 En riesgo","🔴 Crítico")),"⚪ Pendiente") -> 🔴 Crítico
B13: Reducción de mora | C13: Tasa de recuperación | D13: Saldo de cartera recuperada ÷ Saldo de cartera deteriorada | E13: Mide la proporción de cartera recuperada frente a la deteriorada por rodamiento (matriz de transición). | F13: % | G13: Crecer | H13: Mensual | I13: =VLOOKUP("IND-06",Parámetros!$B$6:$F$30,5,FALSE()) -> Por definir | J13: ='IND-06'!C14 -> 0.3 | K13: ='IND-06'!C15 -> 0.3 | L13: ='IND-06'!C16 -> 0.3 | M13: ='IND-06'!C17 -> 0.3 | N13: ='IND-06'!C18 -> 0.3 | O13: =IFERROR(IF('IND-06'!G23="","",'IND-06'!G23),"") | P13: =IFERROR(IF('IND-06'!G24="","",'IND-06'!G24),"") | Q13: =IFERROR(IF('IND-06'!G25="","",'IND-06'!G25),"") | R13: =IFERROR(IF('IND-06'!G26="","",'IND-06'!G26),"") | S13: =IFERROR(IF('IND-06'!G27="","",'IND-06'!G27),"") | T13: =IFERROR(IF('IND-06'!G28="","",'IND-06'!G28),"") | U13: =IFERROR(IF('IND-06'!G29="","",'IND-06'!G29),"") | V13: =IFERROR(IF('IND-06'!G30="","",'IND-06'!G30),"") | W13: =IFERROR(IF('IND-06'!G31="","",'IND-06'!G31),"") | X13: =IFERROR(IF('IND-06'!G32="","",'IND-06'!G32),"") | Y13: =IFERROR(IF('IND-06'!G33="","",'IND-06'!G33),"") | Z13: =IFERROR(IF('IND-06'!G34="","",'IND-06'!G34),"") | AA13: =IFERROR(IF('IND-06'!G35="","",'IND-06'!G35),"") | AB13: =IFERROR(IF('IND-06'!G36="","",'IND-06'!G36),"") | AC13: =IFERROR(IF('IND-06'!G37="","",'IND-06'!G37),"") | AD13: =IFERROR(IF('IND-06'!G38="","",'IND-06'!G38),"") | AE13: =IFERROR(IF('IND-06'!G39="","",'IND-06'!G39),"") | AF13: =IFERROR(IF('IND-06'!G40="","",'IND-06'!G40),"") | AG13: =IFERROR(IF('IND-06'!G41="","",'IND-06'!G41),"") | AH13: =IFERROR(IF('IND-06'!G42="","",'IND-06'!G42),"") | AI13: =IFERROR(IF('IND-06'!G43="","",'IND-06'!G43),"") | AJ13: =IFERROR(IF('IND-06'!G44="","",'IND-06'!G44),"") | AK13: =IFERROR(IF('IND-06'!G45="","",'IND-06'!G45),"") | AL13: =IFERROR(IF('IND-06'!G46="","",'IND-06'!G46),"") | AM13: =IFERROR(IF('IND-06'!G47="","",'IND-06'!G47),"") | AN13: =IFERROR(IF('IND-06'!G48="","",'IND-06'!G48),"") | AO13: =IFERROR(IF('IND-06'!G49="","",'IND-06'!G49),"") | AP13: =IFERROR(IF('IND-06'!G50="","",'IND-06'!G50),"") | AQ13: =IFERROR(IF('IND-06'!G51="","",'IND-06'!G51),"") | AR13: =IFERROR(IF('IND-06'!G52="","",'IND-06'!G52),"") | AS13: =IFERROR(IF('IND-06'!G53="","",'IND-06'!G53),"") | AT13: =IFERROR(IF('IND-06'!G54="","",'IND-06'!G54),"") | AU13: =IFERROR(IF('IND-06'!G55="","",'IND-06'!G55),"") | AV13: =IFERROR(IF('IND-06'!G56="","",'IND-06'!G56),"") | AW13: =IFERROR(IF('IND-06'!G57="","",'IND-06'!G57),"") | AX13: =IFERROR(IF('IND-06'!G58="","",'IND-06'!G58),"") | AY13: =IFERROR(IF('IND-06'!G59="","",'IND-06'!G59),"") | AZ13: =IFERROR(IF('IND-06'!G60="","",'IND-06'!G60),"") | BA13: =IFERROR(IF('IND-06'!G61="","",'IND-06'!G61),"") | BB13: =IFERROR(IF('IND-06'!G62="","",'IND-06'!G62),"") | BC13: =IFERROR(IF('IND-06'!G63="","",'IND-06'!G63),"") | BD13: =IFERROR(IF('IND-06'!G64="","",'IND-06'!G64),"") | BE13: =IFERROR(IF('IND-06'!G65="","",'IND-06'!G65),"") | BF13: =IFERROR(IF('IND-06'!G66="","",'IND-06'!G66),"") | BG13: =IFERROR(IF('IND-06'!G67="","",'IND-06'!G67),"") | BH13: =IFERROR(IF('IND-06'!G68="","",'IND-06'!G68),"") | BI13: =IFERROR(IF('IND-06'!G69="","",'IND-06'!G69),"") | BJ13: =IFERROR(IF('IND-06'!G70="","",'IND-06'!G70),"") | BK13: =IFERROR(IF('IND-06'!G71="","",'IND-06'!G71),"") | BL13: =IFERROR(IF('IND-06'!G72="","",'IND-06'!G72),"") | BM13: =IFERROR(IF('IND-06'!G73="","",'IND-06'!G73),"") | BN13: =IFERROR(IF('IND-06'!G74="","",'IND-06'!G74),"") | BO13: =IFERROR(IF('IND-06'!G75="","",'IND-06'!G75),"") | BP13: =IFERROR(IF('IND-06'!G76="","",'IND-06'!G76),"") | BQ13: =IFERROR(IF('IND-06'!G77="","",'IND-06'!G77),"") | BR13: =IFERROR(IF('IND-06'!G78="","",'IND-06'!G78),"") | BS13: =IFERROR(IF('IND-06'!G79="","",'IND-06'!G79),"") | BT13: =IFERROR(IF('IND-06'!G80="","",'IND-06'!G80),"") | BU13: =IFERROR(IF('IND-06'!G81="","",'IND-06'!G81),"") | BV13: =IFERROR(IF('IND-06'!G82="","",'IND-06'!G82),"") | BW13: =IFERROR(AVERAGE('IND-06'!I23:I34),"") | BX13: =IFERROR(AVERAGE('IND-06'!I35:I46),"") | BY13: =IFERROR(AVERAGE('IND-06'!I47:I58),"") | BZ13: =IFERROR(AVERAGE('IND-06'!I59:I70),"") | CA13: =IFERROR(AVERAGE('IND-06'!I71:I82),"") | CB13: =IFERROR(IF(LOOKUP(2,1/((BW13:CA13<>"")*(ISNUMBER(BW13:CA13))),BW13:CA13)>=0.95,"🟢 Cumple",IF(LOOKUP(2,1/((BW13:CA13<>"")*(ISNUMBER(BW13:CA13))),BW13:CA13)>=0.8,"🟡 En riesgo","🔴 Crítico")),"⚪ Pendiente") -> ⚪ Pendiente
B14: Reducción de mora | C14: Tasa de normalización de cartera | D14: Saldo de normalizaciones al día ÷ Saldo total de normalizaciones | E14: Mide la efectividad de acuerdos de pago y reestructuraciones. | F14: % | G14: Crecer | H14: Mensual | I14: =VLOOKUP("IND-07",Parámetros!$B$6:$F$30,5,FALSE()) -> Por definir | J14: ='IND-07'!C14 -> 0.8 | K14: ='IND-07'!C15 -> 0.8 | L14: ='IND-07'!C16 -> 0.8 | M14: ='IND-07'!C17 -> 0.8 | N14: ='IND-07'!C18 -> 0.8 | O14: =IFERROR(IF('IND-07'!G23="","",'IND-07'!G23),"") | P14: =IFERROR(IF('IND-07'!G24="","",'IND-07'!G24),"") | Q14: =IFERROR(IF('IND-07'!G25="","",'IND-07'!G25),"") | R14: =IFERROR(IF('IND-07'!G26="","",'IND-07'!G26),"") | S14: =IFERROR(IF('IND-07'!G27="","",'IND-07'!G27),"") | T14: =IFERROR(IF('IND-07'!G28="","",'IND-07'!G28),"") | U14: =IFERROR(IF('IND-07'!G29="","",'IND-07'!G29),"") | V14: =IFERROR(IF('IND-07'!G30="","",'IND-07'!G30),"") | W14: =IFERROR(IF('IND-07'!G31="","",'IND-07'!G31),"") | X14: =IFERROR(IF('IND-07'!G32="","",'IND-07'!G32),"") | Y14: =IFERROR(IF('IND-07'!G33="","",'IND-07'!G33),"") | Z14: =IFERROR(IF('IND-07'!G34="","",'IND-07'!G34),"") | AA14: =IFERROR(IF('IND-07'!G35="","",'IND-07'!G35),"") | AB14: =IFERROR(IF('IND-07'!G36="","",'IND-07'!G36),"") | AC14: =IFERROR(IF('IND-07'!G37="","",'IND-07'!G37),"") | AD14: =IFERROR(IF('IND-07'!G38="","",'IND-07'!G38),"") | AE14: =IFERROR(IF('IND-07'!G39="","",'IND-07'!G39),"") | AF14: =IFERROR(IF('IND-07'!G40="","",'IND-07'!G40),"") | AG14: =IFERROR(IF('IND-07'!G41="","",'IND-07'!G41),"") | AH14: =IFERROR(IF('IND-07'!G42="","",'IND-07'!G42),"") | AI14: =IFERROR(IF('IND-07'!G43="","",'IND-07'!G43),"") | AJ14: =IFERROR(IF('IND-07'!G44="","",'IND-07'!G44),"") | AK14: =IFERROR(IF('IND-07'!G45="","",'IND-07'!G45),"") | AL14: =IFERROR(IF('IND-07'!G46="","",'IND-07'!G46),"") | AM14: =IFERROR(IF('IND-07'!G47="","",'IND-07'!G47),"") | AN14: =IFERROR(IF('IND-07'!G48="","",'IND-07'!G48),"") | AO14: =IFERROR(IF('IND-07'!G49="","",'IND-07'!G49),"") | AP14: =IFERROR(IF('IND-07'!G50="","",'IND-07'!G50),"") | AQ14: =IFERROR(IF('IND-07'!G51="","",'IND-07'!G51),"") | AR14: =IFERROR(IF('IND-07'!G52="","",'IND-07'!G52),"") | AS14: =IFERROR(IF('IND-07'!G53="","",'IND-07'!G53),"") | AT14: =IFERROR(IF('IND-07'!G54="","",'IND-07'!G54),"") | AU14: =IFERROR(IF('IND-07'!G55="","",'IND-07'!G55),"") | AV14: =IFERROR(IF('IND-07'!G56="","",'IND-07'!G56),"") | AW14: =IFERROR(IF('IND-07'!G57="","",'IND-07'!G57),"") | AX14: =IFERROR(IF('IND-07'!G58="","",'IND-07'!G58),"") | AY14: =IFERROR(IF('IND-07'!G59="","",'IND-07'!G59),"") | AZ14: =IFERROR(IF('IND-07'!G60="","",'IND-07'!G60),"") | BA14: =IFERROR(IF('IND-07'!G61="","",'IND-07'!G61),"") | BB14: =IFERROR(IF('IND-07'!G62="","",'IND-07'!G62),"") | BC14: =IFERROR(IF('IND-07'!G63="","",'IND-07'!G63),"") | BD14: =IFERROR(IF('IND-07'!G64="","",'IND-07'!G64),"") | BE14: =IFERROR(IF('IND-07'!G65="","",'IND-07'!G65),"") | BF14: =IFERROR(IF('IND-07'!G66="","",'IND-07'!G66),"") | BG14: =IFERROR(IF('IND-07'!G67="","",'IND-07'!G67),"") | BH14: =IFERROR(IF('IND-07'!G68="","",'IND-07'!G68),"") | BI14: =IFERROR(IF('IND-07'!G69="","",'IND-07'!G69),"") | BJ14: =IFERROR(IF('IND-07'!G70="","",'IND-07'!G70),"") | BK14: =IFERROR(IF('IND-07'!G71="","",'IND-07'!G71),"") | BL14: =IFERROR(IF('IND-07'!G72="","",'IND-07'!G72),"") | BM14: =IFERROR(IF('IND-07'!G73="","",'IND-07'!G73),"") | BN14: =IFERROR(IF('IND-07'!G74="","",'IND-07'!G74),"") | BO14: =IFERROR(IF('IND-07'!G75="","",'IND-07'!G75),"") | BP14: =IFERROR(IF('IND-07'!G76="","",'IND-07'!G76),"") | BQ14: =IFERROR(IF('IND-07'!G77="","",'IND-07'!G77),"") | BR14: =IFERROR(IF('IND-07'!G78="","",'IND-07'!G78),"") | BS14: =IFERROR(IF('IND-07'!G79="","",'IND-07'!G79),"") | BT14: =IFERROR(IF('IND-07'!G80="","",'IND-07'!G80),"") | BU14: =IFERROR(IF('IND-07'!G81="","",'IND-07'!G81),"") | BV14: =IFERROR(IF('IND-07'!G82="","",'IND-07'!G82),"") | BW14: =IFERROR(AVERAGE('IND-07'!I23:I34),"") | BX14: =IFERROR(AVERAGE('IND-07'!I35:I46),"") | BY14: =IFERROR(AVERAGE('IND-07'!I47:I58),"") | BZ14: =IFERROR(AVERAGE('IND-07'!I59:I70),"") | CA14: =IFERROR(AVERAGE('IND-07'!I71:I82),"") | CB14: =IFERROR(IF(LOOKUP(2,1/((BW14:CA14<>"")*(ISNUMBER(BW14:CA14))),BW14:CA14)>=0.95,"🟢 Cumple",IF(LOOKUP(2,1/((BW14:CA14<>"")*(ISNUMBER(BW14:CA14))),BW14:CA14)>=0.8,"🟡 En riesgo","🔴 Crítico")),"⚪ Pendiente") -> ⚪ Pendiente
B15: Crecimiento y remuneración de depósitos | C15: Tasa de crecimiento de ahorros | D15: (Saldo final depósitos − Saldo inicial depósitos) ÷ Saldo inicial depósitos | E15: Mide el crecimiento de los depósitos entre periodos. | F15: % | G15: Crecer | H15: Mensual | I15: =VLOOKUP("IND-08",Parámetros!$B$6:$F$30,5,FALSE()) -> Por definir | J15: ='IND-08'!C14 -> ≥ IPC | K15: ='IND-08'!C15 -> ≥ IPC | L15: ='IND-08'!C16 -> ≥ IPC | M15: ='IND-08'!C17 -> ≥ IPC | N15: ='IND-08'!C18 -> ≥ IPC | O15: =IFERROR(IF('IND-08'!F23="","",'IND-08'!F23),"") | P15: =IFERROR(IF('IND-08'!F24="","",'IND-08'!F24),"") | Q15: =IFERROR(IF('IND-08'!F25="","",'IND-08'!F25),"") | R15: =IFERROR(IF('IND-08'!F26="","",'IND-08'!F26),"") | S15: =IFERROR(IF('IND-08'!F27="","",'IND-08'!F27),"") | T15: =IFERROR(IF('IND-08'!F28="","",'IND-08'!F28),"") | U15: =IFERROR(IF('IND-08'!F29="","",'IND-08'!F29),"") | V15: =IFERROR(IF('IND-08'!F30="","",'IND-08'!F30),"") | W15: =IFERROR(IF('IND-08'!F31="","",'IND-08'!F31),"") | X15: =IFERROR(IF('IND-08'!F32="","",'IND-08'!F32),"") | Y15: =IFERROR(IF('IND-08'!F33="","",'IND-08'!F33),"") | Z15: =IFERROR(IF('IND-08'!F34="","",'IND-08'!F34),"") | AA15: =IFERROR(IF('IND-08'!F35="","",'IND-08'!F35),"") | AB15: =IFERROR(IF('IND-08'!F36="","",'IND-08'!F36),"") | AC15: =IFERROR(IF('IND-08'!F37="","",'IND-08'!F37),"") | AD15: =IFERROR(IF('IND-08'!F38="","",'IND-08'!F38),"") | AE15: =IFERROR(IF('IND-08'!F39="","",'IND-08'!F39),"") | AF15: =IFERROR(IF('IND-08'!F40="","",'IND-08'!F40),"") | AG15: =IFERROR(IF('IND-08'!F41="","",'IND-08'!F41),"") | AH15: =IFERROR(IF('IND-08'!F42="","",'IND-08'!F42),"") | AI15: =IFERROR(IF('IND-08'!F43="","",'IND-08'!F43),"") | AJ15: =IFERROR(IF('IND-08'!F44="","",'IND-08'!F44),"") | AK15: =IFERROR(IF('IND-08'!F45="","",'IND-08'!F45),"") | AL15: =IFERROR(IF('IND-08'!F46="","",'IND-08'!F46),"") | AM15: =IFERROR(IF('IND-08'!F47="","",'IND-08'!F47),"") | AN15: =IFERROR(IF('IND-08'!F48="","",'IND-08'!F48),"") | AO15: =IFERROR(IF('IND-08'!F49="","",'IND-08'!F49),"") | AP15: =IFERROR(IF('IND-08'!F50="","",'IND-08'!F50),"") | AQ15: =IFERROR(IF('IND-08'!F51="","",'IND-08'!F51),"") | AR15: =IFERROR(IF('IND-08'!F52="","",'IND-08'!F52),"") | AS15: =IFERROR(IF('IND-08'!F53="","",'IND-08'!F53),"") | AT15: =IFERROR(IF('IND-08'!F54="","",'IND-08'!F54),"") | AU15: =IFERROR(IF('IND-08'!F55="","",'IND-08'!F55),"") | AV15: =IFERROR(IF('IND-08'!F56="","",'IND-08'!F56),"") | AW15: =IFERROR(IF('IND-08'!F57="","",'IND-08'!F57),"") | AX15: =IFERROR(IF('IND-08'!F58="","",'IND-08'!F58),"") | AY15: =IFERROR(IF('IND-08'!F59="","",'IND-08'!F59),"") | AZ15: =IFERROR(IF('IND-08'!F60="","",'IND-08'!F60),"") | BA15: =IFERROR(IF('IND-08'!F61="","",'IND-08'!F61),"") | BB15: =IFERROR(IF('IND-08'!F62="","",'IND-08'!F62),"") | BC15: =IFERROR(IF('IND-08'!F63="","",'IND-08'!F63),"") | BD15: =IFERROR(IF('IND-08'!F64="","",'IND-08'!F64),"") | BE15: =IFERROR(IF('IND-08'!F65="","",'IND-08'!F65),"") | BF15: =IFERROR(IF('IND-08'!F66="","",'IND-08'!F66),"") | BG15: =IFERROR(IF('IND-08'!F67="","",'IND-08'!F67),"") | BH15: =IFERROR(IF('IND-08'!F68="","",'IND-08'!F68),"") | BI15: =IFERROR(IF('IND-08'!F69="","",'IND-08'!F69),"") | BJ15: =IFERROR(IF('IND-08'!F70="","",'IND-08'!F70),"") | BK15: =IFERROR(IF('IND-08'!F71="","",'IND-08'!F71),"") | BL15: =IFERROR(IF('IND-08'!F72="","",'IND-08'!F72),"") | BM15: =IFERROR(IF('IND-08'!F73="","",'IND-08'!F73),"") | BN15: =IFERROR(IF('IND-08'!F74="","",'IND-08'!F74),"") | BO15: =IFERROR(IF('IND-08'!F75="","",'IND-08'!F75),"") | BP15: =IFERROR(IF('IND-08'!F76="","",'IND-08'!F76),"") | BQ15: =IFERROR(IF('IND-08'!F77="","",'IND-08'!F77),"") | BR15: =IFERROR(IF('IND-08'!F78="","",'IND-08'!F78),"") | BS15: =IFERROR(IF('IND-08'!F79="","",'IND-08'!F79),"") | BT15: =IFERROR(IF('IND-08'!F80="","",'IND-08'!F80),"") | BU15: =IFERROR(IF('IND-08'!F81="","",'IND-08'!F81),"") | BV15: =IFERROR(IF('IND-08'!F82="","",'IND-08'!F82),"") | BW15: =IFERROR(AVERAGE('IND-08'!H23:H34),"") | BX15: =IFERROR(AVERAGE('IND-08'!H35:H46),"") | BY15: =IFERROR(AVERAGE('IND-08'!H47:H58),"") | BZ15: =IFERROR(AVERAGE('IND-08'!H59:H70),"") | CA15: =IFERROR(AVERAGE('IND-08'!H71:H82),"") | CB15: =IFERROR(IF(LOOKUP(2,1/((BW15:CA15<>"")*(ISNUMBER(BW15:CA15))),BW15:CA15)>=0.95,"🟢 Cumple",IF(LOOKUP(2,1/((BW15:CA15<>"")*(ISNUMBER(BW15:CA15))),BW15:CA15)>=0.8,"🟡 En riesgo","🔴 Crítico")),"⚪ Pendiente") -> ⚪ Pendiente
B16: Crecimiento y remuneración de depósitos | C16: Rentabilidad real de los depósitos | D16: Tasa promedio ponderada ahorros − IPC | E16: Asegura que la tasa de rendimiento de los depósitos supere la inflación (poder adquisitivo del ahorro). | F16: % vs IPC | G16: Mantener | H16: Mensual | I16: =VLOOKUP("IND-09",Parámetros!$B$6:$F$30,5,FALSE()) -> Por definir | J16: ='IND-09'!C14 -> 0 | K16: ='IND-09'!C15 -> 0 | L16: ='IND-09'!C16 -> 0 | M16: ='IND-09'!C17 -> 0 | N16: ='IND-09'!C18 -> 0 | O16: =IFERROR(IF('IND-09'!G23="","",'IND-09'!G23),"") | P16: =IFERROR(IF('IND-09'!G24="","",'IND-09'!G24),"") | Q16: =IFERROR(IF('IND-09'!G25="","",'IND-09'!G25),"") | R16: =IFERROR(IF('IND-09'!G26="","",'IND-09'!G26),"") | S16: =IFERROR(IF('IND-09'!G27="","",'IND-09'!G27),"") | T16: =IFERROR(IF('IND-09'!G28="","",'IND-09'!G28),"") | U16: =IFERROR(IF('IND-09'!G29="","",'IND-09'!G29),"") | V16: =IFERROR(IF('IND-09'!G30="","",'IND-09'!G30),"") | W16: =IFERROR(IF('IND-09'!G31="","",'IND-09'!G31),"") | X16: =IFERROR(IF('IND-09'!G32="","",'IND-09'!G32),"") | Y16: =IFERROR(IF('IND-09'!G33="","",'IND-09'!G33),"") | Z16: =IFERROR(IF('IND-09'!G34="","",'IND-09'!G34),"") | AA16: =IFERROR(IF('IND-09'!G35="","",'IND-09'!G35),"") | AB16: =IFERROR(IF('IND-09'!G36="","",'IND-09'!G36),"") | AC16: =IFERROR(IF('IND-09'!G37="","",'IND-09'!G37),"") | AD16: =IFERROR(IF('IND-09'!G38="","",'IND-09'!G38),"") | AE16: =IFERROR(IF('IND-09'!G39="","",'IND-09'!G39),"") | AF16: =IFERROR(IF('IND-09'!G40="","",'IND-09'!G40),"") | AG16: =IFERROR(IF('IND-09'!G41="","",'IND-09'!G41),"") | AH16: =IFERROR(IF('IND-09'!G42="","",'IND-09'!G42),"") | AI16: =IFERROR(IF('IND-09'!G43="","",'IND-09'!G43),"") | AJ16: =IFERROR(IF('IND-09'!G44="","",'IND-09'!G44),"") | AK16: =IFERROR(IF('IND-09'!G45="","",'IND-09'!G45),"") | AL16: =IFERROR(IF('IND-09'!G46="","",'IND-09'!G46),"") | AM16: =IFERROR(IF('IND-09'!G47="","",'IND-09'!G47),"") | AN16: =IFERROR(IF('IND-09'!G48="","",'IND-09'!G48),"") | AO16: =IFERROR(IF('IND-09'!G49="","",'IND-09'!G49),"") | AP16: =IFERROR(IF('IND-09'!G50="","",'IND-09'!G50),"") | AQ16: =IFERROR(IF('IND-09'!G51="","",'IND-09'!G51),"") | AR16: =IFERROR(IF('IND-09'!G52="","",'IND-09'!G52),"") | AS16: =IFERROR(IF('IND-09'!G53="","",'IND-09'!G53),"") | AT16: =IFERROR(IF('IND-09'!G54="","",'IND-09'!G54),"") | AU16: =IFERROR(IF('IND-09'!G55="","",'IND-09'!G55),"") | AV16: =IFERROR(IF('IND-09'!G56="","",'IND-09'!G56),"") | AW16: =IFERROR(IF('IND-09'!G57="","",'IND-09'!G57),"") | AX16: =IFERROR(IF('IND-09'!G58="","",'IND-09'!G58),"") | AY16: =IFERROR(IF('IND-09'!G59="","",'IND-09'!G59),"") | AZ16: =IFERROR(IF('IND-09'!G60="","",'IND-09'!G60),"") | BA16: =IFERROR(IF('IND-09'!G61="","",'IND-09'!G61),"") | BB16: =IFERROR(IF('IND-09'!G62="","",'IND-09'!G62),"") | BC16: =IFERROR(IF('IND-09'!G63="","",'IND-09'!G63),"") | BD16: =IFERROR(IF('IND-09'!G64="","",'IND-09'!G64),"") | BE16: =IFERROR(IF('IND-09'!G65="","",'IND-09'!G65),"") | BF16: =IFERROR(IF('IND-09'!G66="","",'IND-09'!G66),"") | BG16: =IFERROR(IF('IND-09'!G67="","",'IND-09'!G67),"") | BH16: =IFERROR(IF('IND-09'!G68="","",'IND-09'!G68),"") | BI16: =IFERROR(IF('IND-09'!G69="","",'IND-09'!G69),"") | BJ16: =IFERROR(IF('IND-09'!G70="","",'IND-09'!G70),"") | BK16: =IFERROR(IF('IND-09'!G71="","",'IND-09'!G71),"") | BL16: =IFERROR(IF('IND-09'!G72="","",'IND-09'!G72),"") | BM16: =IFERROR(IF('IND-09'!G73="","",'IND-09'!G73),"") | BN16: =IFERROR(IF('IND-09'!G74="","",'IND-09'!G74),"") | BO16: =IFERROR(IF('IND-09'!G75="","",'IND-09'!G75),"") | BP16: =IFERROR(IF('IND-09'!G76="","",'IND-09'!G76),"") | BQ16: =IFERROR(IF('IND-09'!G77="","",'IND-09'!G77),"") | BR16: =IFERROR(IF('IND-09'!G78="","",'IND-09'!G78),"") | BS16: =IFERROR(IF('IND-09'!G79="","",'IND-09'!G79),"") | BT16: =IFERROR(IF('IND-09'!G80="","",'IND-09'!G80),"") | BU16: =IFERROR(IF('IND-09'!G81="","",'IND-09'!G81),"") | BV16: =IFERROR(IF('IND-09'!G82="","",'IND-09'!G82),"") | BW16: =IFERROR(AVERAGE('IND-09'!I23:I34),"") | BX16: =IFERROR(AVERAGE('IND-09'!I35:I46),"") | BY16: =IFERROR(AVERAGE('IND-09'!I47:I58),"") | BZ16: =IFERROR(AVERAGE('IND-09'!I59:I70),"") | CA16: =IFERROR(AVERAGE('IND-09'!I71:I82),"") | CB16: =IFERROR(IF(LOOKUP(2,1/((BW16:CA16<>"")*(ISNUMBER(BW16:CA16))),BW16:CA16)>=0.95,"🟢 Cumple",IF(LOOKUP(2,1/((BW16:CA16<>"")*(ISNUMBER(BW16:CA16))),BW16:CA16)>=0.8,"🟡 En riesgo","🔴 Crítico")),"⚪ Pendiente") -> ⚪ Pendiente
B17: Rentabilidad y fortalecimiento patrimonial | C17: Suficiencia del Margen | D17: Margen financiero bruto ÷ Gastos operativos | E17: Evalúa la capacidad del margen financiero bruto para cubrir los gastos operativos. | F17: Veces (x) | G17: Mantener | H17: Mensual | I17: =VLOOKUP("IND-10",Parámetros!$B$6:$F$30,5,FALSE()) -> Por definir | J17: ='IND-10'!C14 -> 1.2 | K17: ='IND-10'!C15 -> 1.2 | L17: ='IND-10'!C16 -> 1.2 | M17: ='IND-10'!C17 -> 1.2 | N17: ='IND-10'!C18 -> 1.2 | O17: =IFERROR(IF('IND-10'!G23="","",'IND-10'!G23),"") | P17: =IFERROR(IF('IND-10'!G24="","",'IND-10'!G24),"") | Q17: =IFERROR(IF('IND-10'!G25="","",'IND-10'!G25),"") | R17: =IFERROR(IF('IND-10'!G26="","",'IND-10'!G26),"") | S17: =IFERROR(IF('IND-10'!G27="","",'IND-10'!G27),"") | T17: =IFERROR(IF('IND-10'!G28="","",'IND-10'!G28),"") | U17: =IFERROR(IF('IND-10'!G29="","",'IND-10'!G29),"") | V17: =IFERROR(IF('IND-10'!G30="","",'IND-10'!G30),"") | W17: =IFERROR(IF('IND-10'!G31="","",'IND-10'!G31),"") | X17: =IFERROR(IF('IND-10'!G32="","",'IND-10'!G32),"") | Y17: =IFERROR(IF('IND-10'!G33="","",'IND-10'!G33),"") | Z17: =IFERROR(IF('IND-10'!G34="","",'IND-10'!G34),"") | AA17: =IFERROR(IF('IND-10'!G35="","",'IND-10'!G35),"") | AB17: =IFERROR(IF('IND-10'!G36="","",'IND-10'!G36),"") | AC17: =IFERROR(IF('IND-10'!G37="","",'IND-10'!G37),"") | AD17: =IFERROR(IF('IND-10'!G38="","",'IND-10'!G38),"") | AE17: =IFERROR(IF('IND-10'!G39="","",'IND-10'!G39),"") | AF17: =IFERROR(IF('IND-10'!G40="","",'IND-10'!G40),"") | AG17: =IFERROR(IF('IND-10'!G41="","",'IND-10'!G41),"") | AH17: =IFERROR(IF('IND-10'!G42="","",'IND-10'!G42),"") | AI17: =IFERROR(IF('IND-10'!G43="","",'IND-10'!G43),"") | AJ17: =IFERROR(IF('IND-10'!G44="","",'IND-10'!G44),"") | AK17: =IFERROR(IF('IND-10'!G45="","",'IND-10'!G45),"") | AL17: =IFERROR(IF('IND-10'!G46="","",'IND-10'!G46),"") | AM17: =IFERROR(IF('IND-10'!G47="","",'IND-10'!G47),"") | AN17: =IFERROR(IF('IND-10'!G48="","",'IND-10'!G48),"") | AO17: =IFERROR(IF('IND-10'!G49="","",'IND-10'!G49),"") | AP17: =IFERROR(IF('IND-10'!G50="","",'IND-10'!G50),"") | AQ17: =IFERROR(IF('IND-10'!G51="","",'IND-10'!G51),"") | AR17: =IFERROR(IF('IND-10'!G52="","",'IND-10'!G52),"") | AS17: =IFERROR(IF('IND-10'!G53="","",'IND-10'!G53),"") | AT17: =IFERROR(IF('IND-10'!G54="","",'IND-10'!G54),"") | AU17: =IFERROR(IF('IND-10'!G55="","",'IND-10'!G55),"") | AV17: =IFERROR(IF('IND-10'!G56="","",'IND-10'!G56),"") | AW17: =IFERROR(IF('IND-10'!G57="","",'IND-10'!G57),"") | AX17: =IFERROR(IF('IND-10'!G58="","",'IND-10'!G58),"") | AY17: =IFERROR(IF('IND-10'!G59="","",'IND-10'!G59),"") | AZ17: =IFERROR(IF('IND-10'!G60="","",'IND-10'!G60),"") | BA17: =IFERROR(IF('IND-10'!G61="","",'IND-10'!G61),"") | BB17: =IFERROR(IF('IND-10'!G62="","",'IND-10'!G62),"") | BC17: =IFERROR(IF('IND-10'!G63="","",'IND-10'!G63),"") | BD17: =IFERROR(IF('IND-10'!G64="","",'IND-10'!G64),"") | BE17: =IFERROR(IF('IND-10'!G65="","",'IND-10'!G65),"") | BF17: =IFERROR(IF('IND-10'!G66="","",'IND-10'!G66),"") | BG17: =IFERROR(IF('IND-10'!G67="","",'IND-10'!G67),"") | BH17: =IFERROR(IF('IND-10'!G68="","",'IND-10'!G68),"") | BI17: =IFERROR(IF('IND-10'!G69="","",'IND-10'!G69),"") | BJ17: =IFERROR(IF('IND-10'!G70="","",'IND-10'!G70),"") | BK17: =IFERROR(IF('IND-10'!G71="","",'IND-10'!G71),"") | BL17: =IFERROR(IF('IND-10'!G72="","",'IND-10'!G72),"") | BM17: =IFERROR(IF('IND-10'!G73="","",'IND-10'!G73),"") | BN17: =IFERROR(IF('IND-10'!G74="","",'IND-10'!G74),"") | BO17: =IFERROR(IF('IND-10'!G75="","",'IND-10'!G75),"") | BP17: =IFERROR(IF('IND-10'!G76="","",'IND-10'!G76),"") | BQ17: =IFERROR(IF('IND-10'!G77="","",'IND-10'!G77),"") | BR17: =IFERROR(IF('IND-10'!G78="","",'IND-10'!G78),"") | BS17: =IFERROR(IF('IND-10'!G79="","",'IND-10'!G79),"") | BT17: =IFERROR(IF('IND-10'!G80="","",'IND-10'!G80),"") | BU17: =IFERROR(IF('IND-10'!G81="","",'IND-10'!G81),"") | BV17: =IFERROR(IF('IND-10'!G82="","",'IND-10'!G82),"") | BW17: =IFERROR(AVERAGE('IND-10'!I23:I34),"") | BX17: =IFERROR(AVERAGE('IND-10'!I35:I46),"") | BY17: =IFERROR(AVERAGE('IND-10'!I47:I58),"") | BZ17: =IFERROR(AVERAGE('IND-10'!I59:I70),"") | CA17: =IFERROR(AVERAGE('IND-10'!I71:I82),"") | CB17: =IFERROR(IF(LOOKUP(2,1/((BW17:CA17<>"")*(ISNUMBER(BW17:CA17))),BW17:CA17)>=0.95,"🟢 Cumple",IF(LOOKUP(2,1/((BW17:CA17<>"")*(ISNUMBER(BW17:CA17))),BW17:CA17)>=0.8,"🟡 En riesgo","🔴 Crítico")),"⚪ Pendiente") -> ⚪ Pendiente
B18: Rentabilidad y fortalecimiento patrimonial | C18: Cumplimiento de pago de aportes sociales | D18: Recaudo real de aportes ÷ Recaudo esperado de aportes | E18: Mide el grado de cumplimiento del recaudo mensual de aportes frente al esperado. | F18: % | G18: Mantener | H18: Mensual | I18: =VLOOKUP("IND-11",Parámetros!$B$6:$F$30,5,FALSE()) -> Por definir | J18: ='IND-11'!C14 -> 0.95 | K18: ='IND-11'!C15 -> 0.95 | L18: ='IND-11'!C16 -> 0.95 | M18: ='IND-11'!C17 -> 0.95 | N18: ='IND-11'!C18 -> 0.95 | O18: =IFERROR(IF('IND-11'!G23="","",'IND-11'!G23),"") | P18: =IFERROR(IF('IND-11'!G24="","",'IND-11'!G24),"") | Q18: =IFERROR(IF('IND-11'!G25="","",'IND-11'!G25),"") | R18: =IFERROR(IF('IND-11'!G26="","",'IND-11'!G26),"") | S18: =IFERROR(IF('IND-11'!G27="","",'IND-11'!G27),"") | T18: =IFERROR(IF('IND-11'!G28="","",'IND-11'!G28),"") | U18: =IFERROR(IF('IND-11'!G29="","",'IND-11'!G29),"") | V18: =IFERROR(IF('IND-11'!G30="","",'IND-11'!G30),"") | W18: =IFERROR(IF('IND-11'!G31="","",'IND-11'!G31),"") | X18: =IFERROR(IF('IND-11'!G32="","",'IND-11'!G32),"") | Y18: =IFERROR(IF('IND-11'!G33="","",'IND-11'!G33),"") | Z18: =IFERROR(IF('IND-11'!G34="","",'IND-11'!G34),"") | AA18: =IFERROR(IF('IND-11'!G35="","",'IND-11'!G35),"") | AB18: =IFERROR(IF('IND-11'!G36="","",'IND-11'!G36),"") | AC18: =IFERROR(IF('IND-11'!G37="","",'IND-11'!G37),"") | AD18: =IFERROR(IF('IND-11'!G38="","",'IND-11'!G38),"") | AE18: =IFERROR(IF('IND-11'!G39="","",'IND-11'!G39),"") | AF18: =IFERROR(IF('IND-11'!G40="","",'IND-11'!G40),"") | AG18: =IFERROR(IF('IND-11'!G41="","",'IND-11'!G41),"") | AH18: =IFERROR(IF('IND-11'!G42="","",'IND-11'!G42),"") | AI18: =IFERROR(IF('IND-11'!G43="","",'IND-11'!G43),"") | AJ18: =IFERROR(IF('IND-11'!G44="","",'IND-11'!G44),"") | AK18: =IFERROR(IF('IND-11'!G45="","",'IND-11'!G45),"") | AL18: =IFERROR(IF('IND-11'!G46="","",'IND-11'!G46),"") | AM18: =IFERROR(IF('IND-11'!G47="","",'IND-11'!G47),"") | AN18: =IFERROR(IF('IND-11'!G48="","",'IND-11'!G48),"") | AO18: =IFERROR(IF('IND-11'!G49="","",'IND-11'!G49),"") | AP18: =IFERROR(IF('IND-11'!G50="","",'IND-11'!G50),"") | AQ18: =IFERROR(IF('IND-11'!G51="","",'IND-11'!G51),"") | AR18: =IFERROR(IF('IND-11'!G52="","",'IND-11'!G52),"") | AS18: =IFERROR(IF('IND-11'!G53="","",'IND-11'!G53),"") | AT18: =IFERROR(IF('IND-11'!G54="","",'IND-11'!G54),"") | AU18: =IFERROR(IF('IND-11'!G55="","",'IND-11'!G55),"") | AV18: =IFERROR(IF('IND-11'!G56="","",'IND-11'!G56),"") | AW18: =IFERROR(IF('IND-11'!G57="","",'IND-11'!G57),"") | AX18: =IFERROR(IF('IND-11'!G58="","",'IND-11'!G58),"") | AY18: =IFERROR(IF('IND-11'!G59="","",'IND-11'!G59),"") | AZ18: =IFERROR(IF('IND-11'!G60="","",'IND-11'!G60),"") | BA18: =IFERROR(IF('IND-11'!G61="","",'IND-11'!G61),"") | BB18: =IFERROR(IF('IND-11'!G62="","",'IND-11'!G62),"") | BC18: =IFERROR(IF('IND-11'!G63="","",'IND-11'!G63),"") | BD18: =IFERROR(IF('IND-11'!G64="","",'IND-11'!G64),"") | BE18: =IFERROR(IF('IND-11'!G65="","",'IND-11'!G65),"") | BF18: =IFERROR(IF('IND-11'!G66="","",'IND-11'!G66),"") | BG18: =IFERROR(IF('IND-11'!G67="","",'IND-11'!G67),"") | BH18: =IFERROR(IF('IND-11'!G68="","",'IND-11'!G68),"") | BI18: =IFERROR(IF('IND-11'!G69="","",'IND-11'!G69),"") | BJ18: =IFERROR(IF('IND-11'!G70="","",'IND-11'!G70),"") | BK18: =IFERROR(IF('IND-11'!G71="","",'IND-11'!G71),"") | BL18: =IFERROR(IF('IND-11'!G72="","",'IND-11'!G72),"") | BM18: =IFERROR(IF('IND-11'!G73="","",'IND-11'!G73),"") | BN18: =IFERROR(IF('IND-11'!G74="","",'IND-11'!G74),"") | BO18: =IFERROR(IF('IND-11'!G75="","",'IND-11'!G75),"") | BP18: =IFERROR(IF('IND-11'!G76="","",'IND-11'!G76),"") | BQ18: =IFERROR(IF('IND-11'!G77="","",'IND-11'!G77),"") | BR18: =IFERROR(IF('IND-11'!G78="","",'IND-11'!G78),"") | BS18: =IFERROR(IF('IND-11'!G79="","",'IND-11'!G79),"") | BT18: =IFERROR(IF('IND-11'!G80="","",'IND-11'!G80),"") | BU18: =IFERROR(IF('IND-11'!G81="","",'IND-11'!G81),"") | BV18: =IFERROR(IF('IND-11'!G82="","",'IND-11'!G82),"") | BW18: =IFERROR(AVERAGE('IND-11'!I23:I34),"") | BX18: =IFERROR(AVERAGE('IND-11'!I35:I46),"") | BY18: =IFERROR(AVERAGE('IND-11'!I47:I58),"") | BZ18: =IFERROR(AVERAGE('IND-11'!I59:I70),"") | CA18: =IFERROR(AVERAGE('IND-11'!I71:I82),"") | CB18: =IFERROR(IF(LOOKUP(2,1/((BW18:CA18<>"")*(ISNUMBER(BW18:CA18))),BW18:CA18)>=0.95,"🟢 Cumple",IF(LOOKUP(2,1/((BW18:CA18<>"")*(ISNUMBER(BW18:CA18))),BW18:CA18)>=0.8,"🟡 En riesgo","🔴 Crítico")),"⚪ Pendiente") -> ⚪ Pendiente
B19: Rentabilidad y fortalecimiento patrimonial | C19: Capital institucional | D19: (Aportes amortizados + Reserva protección aportes + Excedente mes) ÷ Activo | E19: Mide la proporción del patrimonio permanente frente al total de activos. | F19: % | G19: Mantener | H19: Mensual | I19: =VLOOKUP("IND-12",Parámetros!$B$6:$F$30,5,FALSE()) -> Por definir | J19: ='IND-12'!C14 -> 0.15 | K19: ='IND-12'!C15 -> 0.15 | L19: ='IND-12'!C16 -> 0.15 | M19: ='IND-12'!C17 -> 0.15 | N19: ='IND-12'!C18 -> 0.15 | O19: =IFERROR(IF('IND-12'!I23="","",'IND-12'!I23),"") | P19: =IFERROR(IF('IND-12'!I24="","",'IND-12'!I24),"") | Q19: =IFERROR(IF('IND-12'!I25="","",'IND-12'!I25),"") | R19: =IFERROR(IF('IND-12'!I26="","",'IND-12'!I26),"") | S19: =IFERROR(IF('IND-12'!I27="","",'IND-12'!I27),"") | T19: =IFERROR(IF('IND-12'!I28="","",'IND-12'!I28),"") | U19: =IFERROR(IF('IND-12'!I29="","",'IND-12'!I29),"") | V19: =IFERROR(IF('IND-12'!I30="","",'IND-12'!I30),"") | W19: =IFERROR(IF('IND-12'!I31="","",'IND-12'!I31),"") | X19: =IFERROR(IF('IND-12'!I32="","",'IND-12'!I32),"") | Y19: =IFERROR(IF('IND-12'!I33="","",'IND-12'!I33),"") | Z19: =IFERROR(IF('IND-12'!I34="","",'IND-12'!I34),"") | AA19: =IFERROR(IF('IND-12'!I35="","",'IND-12'!I35),"") | AB19: =IFERROR(IF('IND-12'!I36="","",'IND-12'!I36),"") | AC19: =IFERROR(IF('IND-12'!I37="","",'IND-12'!I37),"") | AD19: =IFERROR(IF('IND-12'!I38="","",'IND-12'!I38),"") | AE19: =IFERROR(IF('IND-12'!I39="","",'IND-12'!I39),"") | AF19: =IFERROR(IF('IND-12'!I40="","",'IND-12'!I40),"") | AG19: =IFERROR(IF('IND-12'!I41="","",'IND-12'!I41),"") | AH19: =IFERROR(IF('IND-12'!I42="","",'IND-12'!I42),"") | AI19: =IFERROR(IF('IND-12'!I43="","",'IND-12'!I43),"") | AJ19: =IFERROR(IF('IND-12'!I44="","",'IND-12'!I44),"") | AK19: =IFERROR(IF('IND-12'!I45="","",'IND-12'!I45),"") | AL19: =IFERROR(IF('IND-12'!I46="","",'IND-12'!I46),"") | AM19: =IFERROR(IF('IND-12'!I47="","",'IND-12'!I47),"") | AN19: =IFERROR(IF('IND-12'!I48="","",'IND-12'!I48),"") | AO19: =IFERROR(IF('IND-12'!I49="","",'IND-12'!I49),"") | AP19: =IFERROR(IF('IND-12'!I50="","",'IND-12'!I50),"") | AQ19: =IFERROR(IF('IND-12'!I51="","",'IND-12'!I51),"") | AR19: =IFERROR(IF('IND-12'!I52="","",'IND-12'!I52),"") | AS19: =IFERROR(IF('IND-12'!I53="","",'IND-12'!I53),"") | AT19: =IFERROR(IF('IND-12'!I54="","",'IND-12'!I54),"") | AU19: =IFERROR(IF('IND-12'!I55="","",'IND-12'!I55),"") | AV19: =IFERROR(IF('IND-12'!I56="","",'IND-12'!I56),"") | AW19: =IFERROR(IF('IND-12'!I57="","",'IND-12'!I57),"") | AX19: =IFERROR(IF('IND-12'!I58="","",'IND-12'!I58),"") | AY19: =IFERROR(IF('IND-12'!I59="","",'IND-12'!I59),"") | AZ19: =IFERROR(IF('IND-12'!I60="","",'IND-12'!I60),"") | BA19: =IFERROR(IF('IND-12'!I61="","",'IND-12'!I61),"") | BB19: =IFERROR(IF('IND-12'!I62="","",'IND-12'!I62),"") | BC19: =IFERROR(IF('IND-12'!I63="","",'IND-12'!I63),"") | BD19: =IFERROR(IF('IND-12'!I64="","",'IND-12'!I64),"") | BE19: =IFERROR(IF('IND-12'!I65="","",'IND-12'!I65),"") | BF19: =IFERROR(IF('IND-12'!I66="","",'IND-12'!I66),"") | BG19: =IFERROR(IF('IND-12'!I67="","",'IND-12'!I67),"") | BH19: =IFERROR(IF('IND-12'!I68="","",'IND-12'!I68),"") | BI19: =IFERROR(IF('IND-12'!I69="","",'IND-12'!I69),"") | BJ19: =IFERROR(IF('IND-12'!I70="","",'IND-12'!I70),"") | BK19: =IFERROR(IF('IND-12'!I71="","",'IND-12'!I71),"") | BL19: =IFERROR(IF('IND-12'!I72="","",'IND-12'!I72),"") | BM19: =IFERROR(IF('IND-12'!I73="","",'IND-12'!I73),"") | BN19: =IFERROR(IF('IND-12'!I74="","",'IND-12'!I74),"") | BO19: =IFERROR(IF('IND-12'!I75="","",'IND-12'!I75),"") | BP19: =IFERROR(IF('IND-12'!I76="","",'IND-12'!I76),"") | BQ19: =IFERROR(IF('IND-12'!I77="","",'IND-12'!I77),"") | BR19: =IFERROR(IF('IND-12'!I78="","",'IND-12'!I78),"") | BS19: =IFERROR(IF('IND-12'!I79="","",'IND-12'!I79),"") | BT19: =IFERROR(IF('IND-12'!I80="","",'IND-12'!I80),"") | BU19: =IFERROR(IF('IND-12'!I81="","",'IND-12'!I81),"") | BV19: =IFERROR(IF('IND-12'!I82="","",'IND-12'!I82),"") | BW19: =IFERROR(AVERAGE('IND-12'!K23:K34),"") | BX19: =IFERROR(AVERAGE('IND-12'!K35:K46),"") | BY19: =IFERROR(AVERAGE('IND-12'!K47:K58),"") | BZ19: =IFERROR(AVERAGE('IND-12'!K59:K70),"") | CA19: =IFERROR(AVERAGE('IND-12'!K71:K82),"") | CB19: =IFERROR(IF(LOOKUP(2,1/((BW19:CA19<>"")*(ISNUMBER(BW19:CA19))),BW19:CA19)>=0.95,"🟢 Cumple",IF(LOOKUP(2,1/((BW19:CA19<>"")*(ISNUMBER(BW19:CA19))),BW19:CA19)>=0.8,"🟡 En riesgo","🔴 Crítico")),"⚪ Pendiente") -> ⚪ Pendiente
